Workbook
Name YESNO: Lkup!$A$1:$A$2

Sheet Patient_Info
A1: UCSF Adult Vancomycin Dosing Calculator | B1: Enter information in fields outlined in red
A2: Patient Information | B2: Calculated values in blue
A3: *Disclaimer* Use of this tool does not replace clinical judgment.
A4: Input Patient Parameters
A5: Patient Age (years) | B5: 67
A6: Gender | B6: MALE | E6: Enter | F6: Conversion
A7: Weight (kg) | B7: 183.5 | C7: Enter lbs to convert to kg | E7: 250 | F7: =E7/2.2 -> 113.63636
A8: Height (cm) | B8: 168 | C8: Enter inches to convert to cm | E8: 72 | F8: =E8*2.54 -> 182.88
A9: Serum creatinine (mg/L) | B9: 1.24
A11: Assess Patient Clearance
A12: Is patient on intermittent HD? | B12: NO | C12: If YES, see UCSF dosing card for correct dose
A13: Is patient on CRRT? | B13: NO | C13: If YES, see UCSF dosing card for correct dose
A14: Is patient's renal function stable? | B14: YES | C14: IF NO, calculations will be unreliable. Suggest ad hoc dosing and following vancomycin levels.
A15: Total Body Weight/Ideal Body Weight Ratio | B15: =Calculation_Details!C6 -> 2.8615509 | C15: If TBW/IBW>1.2, consider using Adjusted (method 2) or Ideal (method 3) Body Weight in CrCl calculation
A16: Age>65 and SCr<1 | B16: NO | C16: If YES or patient with low muscle mass, consider rounding serum creatinine up to 1 in CrCl calculation (method 4)
A18: Estimators of Creatinine Clearance
A19: Cockroft-Gault using Total Body Weight (TBW) | B19: =Calculation_Details!A12 -> 150 | C19: Method 1 (CrCl maximum capped at 150 ml/min)
A20: Cockroft-Gault using Adjusted Body Weight (AdjBW) | B20: =Calculation_Details!B12 -> 91.475378 | C20: Method 2 (CrCl maximum capped at 150 ml/min)
A21: Cockroft-Gault using Ideal Body Weight (IBW) | B21: =Calculation_Details!C12 -> 52.432828 | C21: Method 3 (CrCl maximum capped at 150 ml/min)
A22: Cockroft-Gault using TBW and SCr rounded up to 1 | B22: =Calculation_Details!D12 -> 150 | C22: Method 4 (CrCl maximum capped at 150 ml/min)
A23: Input Custom CrCl estimation | B23: 42 | C23: Method 5
A25: Select Best Estimator of Creatinine Clearance | B25: 2 | C25: Select 1-5 from Methods Above
A27: To select or evaluate an initial vancomycin dose, click here
A28: To evaluate a vancomycin dosing regimen with a single trough level, click here
A29: To evaluate a vancomycin dosing regimen with two postdistributional levels, click here
A30: To record patient information for follow-up/QI, click here

Sheet Vanco_InitialDose
A1: UCSF Adult Vancomycin Dosing Calculator | B1: Enter information in fields outlined in red
A2: Select or Evaluate Vancomycin Dose | B2: Calculated values in blue
A4: Select Vancomycin Dosing Regimen
A5: Recommended Dosing Interval (hours) | B5: =Calculation_Details!A23 -> 24
A6: Chosen Dosing Interval (hours) | B6: 12 | C6: Select 6,8,12,24 hours
A8: Recommended Vancomycin Dose (mg) | B8: =Calculation_Details!A26 -> 903.58315 | C8: Dose to achieve a steady-state trough of 15 mg/L
A9: Chosen Vancomycin Dose (mg) | B9: 1000 | C9: Select 250,500,750,1000,1250,1500,2000mg
A11: Predicted Vancomycin AUC24 | B11: =Calculation_Details!B29 -> 485.86238 | C11: Target AUC24 is >350
A12: Predicted Vancomycin Trough (mg/L) | B12: =Calculation_Details!D26 -> 16.600575 | C12: Acceptable vancomycin troughs should be <21 to reduce nephrotoxicity
A13: Predicted Vancomycin Peak (mg/L) | B13: =Calculation_Details!C26 -> 22.87178 | C13: Acceptable vancomycin peaks should be <75 to reduce ototoxicity
A15: Recommended Loading Dose (mg) | B15: =Calculation_Details!D29 -> 4495.75 | C15: Loading doses are recommended for patients with severe infections (round to nearest 250mg, cap at 2000mg)
A17: Monitoring
A18: Vancomycin half-life | B18: =Calculation_Details!D20 -> 21.624726 | C18: Steady-state is approximately reached after 4 half-lives of continuous dosing
C19: For routine monitoring, draw trough level before the 4th dose if dosing interval ≥ half-life
C20: If loading dose given, draw draw trough level before the 4th dose of the maintenance regimen
C21: If dosing interval substantially < half-life, draw level before next dose after 3 half-lives have passed
A22: To return to patient information tab, click here
A23: To view calculation details, click here
A24: To record patient information for follow-up/QI, click here

Sheet Vanco_DoseRevisionTrough
A1: UCSF Adult Vancomycin Dosing Calculator | B1: Enter information in fields outlined in red
A2: Evaluate vancomycin dosing regimen based on single trough | B2: Calculated values in blue
A4: Enter Vancomycin Dosing Regimen
A5: Vancomycin Dose (mg) | B5: 500
A6: Vancomycin Frequency (hours) | B6: 12
A8: Dose Revisions based on Single Steady-state Trough | B8: Note: assumes vancomycin volume of distribution is constant; obesity, fluid overload, or burns
A9: Level drawn at steady-state (after >3 half-lives?) | B9: YES | C9: If NO, trough will be UNDERestimated and calculations unreliable
A10: Level drawn <= 30 min before end of dosing interval? | B10: YES | C10: If NO, trough will be OVERestimated and calculations unreliable
A11: Vancomycin trough serum concentration (mg/L) | B11: 8.8
A13: Select Revised Vancomycin Dosing Regimen
A14: Recommended Dosing Interval (hours) | B14: =Calculation_Details!A39 -> 24
A15: Select New Dosing Interval (Hours) | B15: 12 | C15: Select 6,8,12,24 hours
A17: Recommended Vancomycin Dose (mg) | B17: =Calculation_Details!A42 -> 852.27273 | C17: Dose to achieve a steady-state trough of 15 mg/L
A18: Chosen Vancomycin Dose (mg) | B18: 750 | C18: Select 250,500,750,1000,1250,1500,2000mg
A20: Predicted Vancomycin AUC24 | B20: =Calculation_Details!B45 -> 382.59858 | C20: Target AUC24 is >350
A21: Predicted Vancomycin Trough (mg/L) | B21: =Calculation_Details!D42 -> 13.2 | C21: Acceptable vancomycin troughs should be <21 to reduce nephrotoxicity
A22: Predicted Vancomycin Peak (mg/L) | B22: =Calculation_Details!C42 -> 17.9114 | C22: Acceptable vancomycin peaks should be <75 to reduce ototoxicity
A24: Monitoring
A25: Vancomycin half-life | B25: =Calculation_Details!B36 -> 22.704892 | C25: Steady-state is approximately reached after 4 half-lives of continuous dosing
C26: For routine monitoring, draw trough level before the 4th dose if dosing interval ≥ half-life
C27: If loading dose given, draw draw trough level before the 4th dose of the maintenance regimen
C28: If dosing interval substantially < half-life, draw level before next dose after 3 half-lives have passed
A29: To return to patient information tab, click here
A30: To view calculation details, click here
A31: To return to patient information tab, click here

Sheet Vanco_DoseRevisionTwoLevels
A1: UCSF Adult Vancomycin Dosing Calculator | B1: Enter information in fields outlined in red
A2: Evaluate vancomycin dosing regimen based two levels | B2: Calculated values in blue
A4: Enter Vancomycin Dosing Regimen
A5: Vancomycin Dose (mg)
A6: Vancomycin Frequency (hours)
A8: Dose Revisions based on Paired Vancomycin Levels
A9: Initial vancomycin serum concentration (mg/L) | B9: 44.7 | C9: Should be drawn AFTER distribution, at least 1 hour after end of infusion
A10: Time first level drawn AFTER end of infusion (hours) | B10: 1
A11: Time BETWEEN serum concentrations (hours) | B11: 8.25
A12: Second vancomycin serum concentration (mg/L) | B12: 25.9 | C12: Recommended to be trough concentration, no greater than 30 minutes before next dose
A13: Time level drawn BEFORE next dose (hours) | B13: 0.5
A15: Select Revised Vancomycin Dosing Regimen
A16: Recommended Dosing Interval (hours) | B16: =Calculation_Details!A55 -> 12
A17: Chosen Dosing Interval (Hours) | B17: 12 | C17: Select 6,8,12,24 hours
A19: Recommended Vancomycin Dose (mg) | B19: =Calculation_Details!A58 -> 774.83301 | C19: Dose to achieve a steady-state trough of 15 mg/L
A20: Chosen Vancomycin Dose (mg) | B20: 750 | C20: Select 250,500,750,1000,1250,1500,2000mg
A22: Predicted Vancomycin AUC24 | B22: =Calculation_Details!B61 -> 531.94623 | C22: Target AUC24 is >350
A23: Predicted Vancomycin Trough (mg/L) | B23: =Calculation_Details!D58 -> 14.519258 | C23: Acceptable vancomycin troughs should be <21 to reduce nephrotoxicity
A24: Predicted Vancomycin Peak (mg/L) | B24: =Calculation_Details!C58 -> 28.13368 | C24: Acceptable vancomycin peaks should be <75 to reduce ototoxicity
A26: Monitoring
A27: Vancomycin half-life | B27: =Calculation_Details!B52 -> 10.476324 | C27: Steady-state is approximately reached after 4 half-lives of continuous dosing
C28: For routine monitoring, draw trough level before the 4th dose if dosing interval ≥ half-life
C29: If loading dose given, draw draw trough level before the 4th dose of the maintenance regimen
C30: If dosing interval substantially < half-life, draw level before next dose after 3 half-lives have passed
A31: To return to patient information tab, click here
A32: To view calculation details, click here
A33: To record patient information for follow-up/QI, click here

Sheet Calculation_Details
A1: Patient Parameters
A2: Age | B2: Weight (kg) | C2: Height (cm) | D2: SCr | E2: Female
A3: =Patient_Info!B5 -> 67 | B3: =Patient_Info!B7 -> 183.5 | C3: =Patient_Info!B8 -> 168 | D3: =Patient_Info!B9 -> 1.24 | E3: =IF(Patient_Info!B6="FEMALE",1,0) -> 0
A5: IBW | B5: ABW | C5: TBW/IBW | D5: Elderly Flag | E5: Height (in)
A6: =IF(E3=1,(45.5+(2.3*(E6-60))),(50+(2.3*(E6-60)))) -> 64.126066 | B6: =0.4*(B3-A6)+A6 -> 111.87564 | C6: =B3/A6 -> 2.8615509 | D6: =IF(AND(A3>65,D3<1),"YES","NO") -> NO | E6: =C3*0.393701 -> 66.141768
A8: TBW | B8: AdjBW | C8: IBW | D8: TBW & Round SCr | E8: Forced CrCl
A9: CrCl (ml/min) | B9: CrCl (ml/min) | C9: CrCl (ml/min) | D9: CrCl (ml/min) | E9: CrCl (ml/min)
A10: =IF(E3<=0,((140-A3)*B3)/((72)*(D3)),(0.85*((140-A3)*B3/(72*D3)))) -> 150.0392 | B10: =IF(E3<=0,((140-A3)*B6)/((72)*(D3)),(0.85*((140-A3)*B6/(72*D3)))) -> 91.475378 | C10: =IF(E3<=0,((140-A3)*A6)/((72)*(D3)),(0.85*((140-A3)*A6/(72*D3)))) -> 52.432828 | D10: =IF(E3<=0,((140-A3)*B3)/((72)),(0.85*((140-A3)*B3/(72*1)))) -> 186.04861 | E10: =Patient_Info!B23 -> 42
A11: Maximum cutoff 150 ml/min
A12: =IF(A10>150,150,A10) -> 150 | B12: =IF(B10>150,150,B10) -> 91.475378 | C12: =IF(C10>150,150,C10) -> 52.432828 | D12: =IF(D10>150,150,D10) -> 150 | E12: =IF(E10>150,150,E10) -> 42
A13: CrCl (L/hr) | B13: CrCl (L/hr) | C13: CrCl (L/hr) | D13: CrCl (L/hr) | E13: CrCl (L/hr)
A14: =(A12*60)/1000 -> 9 | B14: =(B12*60)/1000 -> 5.4885227 | C14: =(C12*60)/1000 -> 3.1459697 | D14: =(D12*60)/1000 -> 9 | E14: =(E12*60)/1000 -> 2.52
A16: Select Dosing CrCl: 1 for TBW, 2 for ABW, 3 for IBW, 4 for TBW & Rounded SCr, 5 to force CrCl
A17: =Patient_Info!B25 -> 2
A18: Vanco Initial Dosing
A19: Vd_vanc | B19: Clvanc | C19: k | D19: t1/2
A20: =0.7*B3 -> 128.45 | B20: =IF(A17=1,A14*0.75,IF(A17=2,B14*0.75,IF(A17=3,C14*0.75,IF(A17=4,D14*0.75,IF(A17=5,E14*0.75))))) -> 4.116392 | C20: =B20/A20 -> 0.032046648 | D20: =0.693/C20 -> 21.624726
A22: Suggested T | B22: Chosen Tau | C22: Target trough | D22: (-kT) | E22: tpeak | F22: (-ktpeak)
A23: =IF(D20<6,6,IF(AND(D20>6,D20<=10),8,IF(AND(D20>10,D20<=18),12,IF(D20>18,24)))) -> 24 | B23: =Vanco_InitialDose!B6 -> 12 | C23: 15 | D23: =-1*(C20*B23) -> -0.38455978 | E23: =E26+1 -> 2 | F23: =(C20*-E23) -> -0.064093297
A25: Vanco dose | B25: Dose chosen | C25: Predicted peak | D25: Predicted trough | E25: Infusion Time
A26: =((C23*A20)*(1-EXP(D23))) / EXP(D23) -> 903.58315 | B26: =Vanco_InitialDose!B9 -> 1000 | C26: =((B26/A20)*EXP(F23))/(1-EXP(D23)) -> 22.87178 | D26: =((B26/A20)*EXP(D23))/(1-EXP(D23)) -> 16.600575 | E26: =IF(B26<=1000,1,IF(B26=1500,1.5,IF(B26=2000,2))) -> 1
A28: Daily Dose | B28: AUC | C28: Target Peak | D28: Loading Dose | E28: Loading Dose | F28: Peak1
A29: =(B26*(24/B23)) -> 2000 | B29: =A29/B20 -> 485.86238 | C29: 35 | D29: =C29*A20 -> 4495.75 | E29: 2000 | F29: =E29/A20 -> 15.570261
A31: Vanco Dose Revision: Single Trough Level
A32: Interval | B32: Trough level | C32: calc field
A33: =Vanco_DoseRevisionTrough!B6 -> 12 | B33: =Vanco_DoseRevisionTrough!B11 -> 8.8 | C33: =(B33+(Vanco_DoseRevisionTrough!B5/A20))/B33 -> 1.442337
A35: k | B35: t1/2 | C35: Clvanc
A36: =LN(C33)/A33 -> 0.030522057 | B36: =0.693/A36 -> 22.704892 | C36: =A36*A20 -> 3.9205582
A38: Suggested T | B38: Chosen T | C38: Target Trough | D38: (-kT) | E38: tpeak | F38: (-ktpeak)
A39: =IF(B36<6,6,IF(AND(B36>6,B36<=10),8,IF(AND(B36>10,B36<=18),12,IF(B36>18,24)))) -> 24 | B39: =Vanco_DoseRevisionTrough!B15 -> 12 | C39: 15 | D39: =-1*(A36*B39) -> -0.36626468 | E39: =E26+1 -> 2 | F39: =(A36*-E39) -> -0.061044114
A41: Vanco dose | B41: Dose chosen | C41: Predicted peak | D41: Predicted trough
A42: =((C39*A20)*(1-EXP(D39))) / EXP(D39) -> 852.27273 | B42: =Vanco_DoseRevisionTrough!B18 -> 750 | C42: =((B42/A20)*EXP(F39))/(1-EXP(D39)) -> 17.9114 | D42: =((B42/A20)*EXP(D39))/(1-EXP(D39)) -> 13.2
A44: Daily Dose | B44: AUC | C44: Target Peak | D44: Loading Dose
A45: =(B42*(24/B39)) -> 1500 | B45: =A45/C36 -> 382.59858 | C45: 35 | D45: =(C45-B33)*A20 -> 3365.39
A47: Vanco Dose Revision: Paired Levels
A48: Level 1 | B48: Level 1 time post infusion | C48: Interval | D48: Level 2 time before trough | E48: Level 2 | F48: Cpeak | G48: Ctrough
A49: =Vanco_DoseRevisionTwoLevels!B9 -> 44.7 | B49: =Vanco_DoseRevisionTwoLevels!B10 -> 1 | C49: =Vanco_DoseRevisionTwoLevels!B11 -> 8.25 | D49: =Vanco_DoseRevisionTwoLevels!B13 -> 0.5 | E49: =Vanco_DoseRevisionTwoLevels!B12 -> 25.9 | F49: =(A49)/(EXP((A52)*-B49)) -> 47.756857 | G49: =(E49)/(EXP((A52)*-D49)) -> 26.770955
A51: k | B51: t1/2 | C51: Clvanc | D51: Vvanc
A52: =(LN(A49/E49))/C49 -> 0.066149156 | B52: =0.693/A52 -> 10.476324 | C52: =D52*A52 -> 2.8198339 | D52: =((B26/E26)*(1-(EXP(A52*-E26)))/(A52*(F49-(G49*(EXP(A52*-E26)))))) -> 42.628418
A54: Suggested T | B54: Chosen T | C54: Target Trough | D54: (-kT) | E54: tpeak | F54: (-ktpeak)
...

Sheet Pick
A1: YES | B1: 1 | C1: 6 | D1: 250 | E1: MALE
A2: NO | B2: 2 | C2: 8 | D2: 500 | E2: FEMALE
B3: 3 | C3: 12 | D3: 750
B4: 4 | C4: 24 | D4: 1000
B5: 5 | D5: 1250
D6: 1500
D7: 2000

Sheet Sheet2
A2: 24 | B2: 250
A3: 24 | B3: 500
A4: 24 | B4: 750
A5: 24 | B5: 1000
A6: 24 | B6: 1250
A7: 24 | B7: 1500
A8: 24 | B8: 2000
A9: 12 | B9: 250
A10: 12 | B10: 500
A11: 12 | B11: 750
A12: 12 | B12: 1000
A13: 12 | B13: 1250
... A29: 6 | B29: 2000

Sheet Sheet3
A1: 45 | B1: 10 | C1: 250 | D1: 6
A2: 46 | B2: 11 | C2: 500 | D2: 8
A3: 47 | B3: 12 | C3: 750 | D3: 12
A4: 48 | B4: 13 | C4: 1000 | D4: 24
A5: 49 | B5: 14 | C5: 1250
A6: 50 | B6: 15 | C6: 1500
A7: 51 | B7: 16 | C7: 2000
A8: 52 | B8: 17
A9: 53 | B9: 18
A10: 54 | B10: 19
A11: 55 | B11: 20
A12: 56 | B12: 21
A13: 57 | B13: 22
A14: 58 | B14: 23
A15: 59 | B15: 24
A16: 60 | B16: 25
A17: 61 | B17: 26
A18: 62 | B18: 27
A19: 63 | B19: 28
... A76: 120 | B76: 85
B77: 86
B78: 87
B79: 88
B80: 89
B81: 90
B82: 91
B83: 92
B84: 93
B85: 94
B86: 95
B87: 96
B88: 97
... B131: 140

Sheet Lkup
A1: YES
A2: NO
